Workbook

Sheet Комментарии
A1: 1 | B1: При сложении двух положительных слагаемых получено положительное число. Результат выполнения операции верный и корректный, совпадает с суммой десятичных эквивалентов. | AJ1: =IF(AF1-POWER(2,AJ$3)<0,0,1) -> 0 | AK1: =IF(AF1 - AJ1*POWER(2,AJ$3) - POWER(2,AK$3)<0, 0,1) -> 0 | AL1: =IF(AF1 - AJ1*POWER(2,AJ$3) - AK1 * POWER(2,AK$3) - POWER(2,AL$3)<0, 0,1) -> 0 | AM1: =IF(AF1 - AJ1*POWER(2,AJ$3) -AK1*POWER(2,AK$3)-AL1*POWER(2,AL$3)-POWER(2,AM$3)<0,0,1) -> 0 | AN1: . | AO1: =IF(AF1 - AJ1*POWER(2,AJ$3)-AK1*POWER(2,AK$3)-AL1*POWER(2,AL$3)-AM1*POWER(2,AM$3)-POWER(2,AO$3)<0,0,1) -> 0 | AP1: =IF(AF1 - AJ1*POWER(2,AJ$3)-AK1*POWER(2,AK$3)-AL1*POWER(2,AL$3)-AM1*POWER(2,AM$3)-AO1*POWER(2,AO$3)-POWER(2,AP$3)<0,0,1) -> 0 | AQ1: =IF(AF1 - AJ1*POWER(2,AJ$3)-AK1*POWER(2,AK$3)-AL1*POWER(2,AL$3)-AM1*POWER(2,AM$3)-AO1*POWER(2,AO$3)-AP1*POWER(2,AP$3)-POWER(2,AQ$3)<0,0,1) -> 0 | AR1: =IF(AF1 - AJ1*POWER(2,AJ$3)-AK1*POWER(2,AK$3)-AL1*POWER(2,AL$3)-AM1*POWER(2,AM$3)-AO1*POWER(2,AO$3)-AP1*POWER(2,AP$3)-AQ1*POWER(2,AQ$3)-POWER(2,AR$3)<0,0,1) -> 0 | AS1: . | AT1: =IF(AF1 - AJ1*POWER(2,AJ$3)-AK1*POWER(2,AK$3)-AL1*POWER(2,AL$3)-AM1*POWER(2,AM$3)-AO1*POWER(2,AO$3)-AP1*POWER(2,AP$3)-AQ1*POWER(2,AQ$3)-AR1*POWER(2,AR$3)-POWER(2,AT$3)<0,0,1) -> 0 | AU1: =IF(AF1 - AJ1*POWER(2,AJ$3)-AK1*POWER(2,AK$3)-AL1*POWER(2,AL$3)-AM1*POWER(2,AM$3)-AO1*POWER(2,AO$3)-AP1*POWER(2,AP$3)-AQ1*POWER(2,AQ$3)-AR1*POWER(2,AR$3)-AT1*POWER(2,AT$3)-POWER(2,AU$3)<0,0,1) -> 0 | AV1: =IF(AF1 - AJ1*POWER(2,AJ$3)-AK1*POWER(2,AK$3)-AL1*POWER(2,AL$3)-AM1*POWER(2,AM$3)-AO1*POWER(2,AO$3)-AP1*POWER(2,AP$3)-AQ1*POWER(2,AQ$3)-AR1*POWER(2,AR$3)-AT1*POWER(2,AT$3)-AU1*POWER(2,AU$3)-POWER(2,AV$3)<0,0,1) -> 0 | AW1: =IF(AF1 - AJ1*POWER(2,AJ$3)-AK1*POWER(2,AK$3)-AL1*POWER(2,AL$3)-AM1*POWER(2,AM$3)-AO1*POWER(2,AO$3)-AP1*POWER(2,AP$3)-AQ1*POWER(2,AQ$3)-AR1*POWER(2,AR$3)-AT1*POWER(2,AT$3)-AU1*POWER(2,AU$3)-AV1*POWER(2,AV$3)-POWER(2,AW$3)<0,0,1) -> 0 | AX1: . | AY1: =IF(AF1 - AJ1*POWER(2,AJ$3)-AK1*POWER(2,AK$3)-AL1*POWER(2,AL$3)-AM1*POWER(2,AM$3)-AO1*POWER(2,AO$3)-AP1*POWER(2,AP$3)-AQ1*POWER(2,AQ$3)-AR1*POWER(2,AR$3)-AT1*POWER(2,AT$3)-AU1*POWER(2,AU$3)-AV1*POWER(2,AV$3)-AW1*POWER(2,AW$3)-POWER(2,AY$3)<0,0,1) -> 0 | AZ1: =IF(AF1 - AJ1*POWER(2,AJ$3)-AK1*POWER(2,AK$3)-AL1*POWER(2,AL$3)-AM1*POWER(2,AM$3)-AO1*POWER(2,AO$3)-AP1*POWER(2,AP$3)-AQ1*POWER(2,AQ$3)-AR1*POWER(2,AR$3)-AT1*POWER(2,AT$3)-AU1*POWER(2,AU$3)-AV1*POWER(2,AV$3)-AW1*POWER(2,AW$3)-AY1*POWER(2,AY$3)-POWER(2,AZ$3)<0,0,1) -> 0 | BA1: =IF(AF1 - AJ1*POWER(2,AJ$3)-AK1*POWER(2,AK$3)-AL1*POWER(2,AL$3)-AM1*POWER(2,AM$3)-AO1*POWER(2,AO$3)-AP1*POWER(2,AP$3)-AQ1*POWER(2,AQ$3)-AR1*POWER(2,AR$3)-AT1*POWER(2,AT$3)-AU1*POWER(2,AU$3)-AV1*POWER(2,AV$3)-AW1*POWER(2,AW$3)-AY1*POWER(2,AY$3)-AZ1*POWER(2,AZ$3)-POWER(2,BA$3)<0,0,1) -> 0 | BB1: =IF(AF1 - AJ1*POWER(2,AJ$3)-AK1*POWER(2,AK$3)-AL1*POWER(2,AL$3)-AM1*POWER(2,AM$3)-AO1*POWER(2,AO$3)-AP1*POWER(2,AP$3)-AQ1*POWER(2,AQ$3)-AR1*POWER(2,AR$3)-AT1*POWER(2,AT$3)-AU1*POWER(2,AU$3)-AV1*POWER(2,AV$3)-AW1*POWER(2,AW$3)-AY1*POWER(2,AY$3)-AZ1*POWER(2,AZ$3)-BA1*POWER(2,BA$3)-POWER(2,BB$3)<0,0,1) -> 0
A2: 2 | B2: При сложении двух положительных слагаемых получен отрицательный результат. ПЕРЕПОЛНЕНИЕ! Результат выполнения операции некорректный, не совпадает с суммой десятичных эквивалентов.
A3: 3 | B3: При сложении положительного и отрицательного слагаемых получено отрицательное число. Результат выполнения операции верный и корректный, совпадает с суммой десятичных эквивалентов.
A4: 4 | B4: При сложении положительного и отрицательного слагаемых получено положительное число. Перенос из старшего разряда не учитывается. Результат выполнения операции верный и корректный, совпадает с суммой десятичных эквивалентов.
A5: 5 | B5: При сложении двух отрицательных слагаемых получено отрицательное число. Перенос из старшего разряда не учитывается. Результат выполнения операции верный и корректный, совпадает с суммой десятичных эквивалентов.
A6: 6 | B6: При сложении двух отрицательных слагаемых получено положительное число. ПЕРЕПОЛНЕНИЕ! Результат выполнения операции некорректный, не совпадает с суммой десятичных эквивалентов.

Sheet Основное
B2: A= | C2: =3307 -> 3307 | F2: [-2^15;2^15-1]
B3: C= | C3: =20458 -> 20458 | F3: [-2^15;2^15-1]
A5: X1= | B5: A = | C5: =C2 -> 3307 | E5: B1= | G5: =MID(VLOOKUP(MID(IF(LEN(DEC2HEX(C5,4))>=4,MID(TEXT(DEC2HEX(C5,4),"0"),LEN(TEXT(DEC2HEX(C5,4),"0"))-3,4),DEC2HEX(C5,4)),1,1),'двоичные коды'!A$1:B$16,2,0),1,1) -> 0 | H5: =MID(VLOOKUP(MID(IF(LEN(DEC2HEX(C5,4))>=4,MID(TEXT(DEC2HEX(C5,4),"0"),LEN(TEXT(DEC2HEX(C5,4),"0"))-3,4),DEC2HEX(C5,4)),1,1),'двоичные коды'!A$1:B$16,2,0),2,1) -> 0 | I5: =MID(VLOOKUP(MID(IF(LEN(DEC2HEX(C5,4))>=4,MID(TEXT(DEC2HEX(C5,4),"0"),LEN(TEXT(DEC2HEX(C5,4),"0"))-3,4),DEC2HEX(C5,4)),1,1),'двоичные коды'!A$1:B$16,2,0),3,1) -> 0 | J5: =MID(VLOOKUP(MID(IF(LEN(DEC2HEX(C5,4))>=4,MID(TEXT(DEC2HEX(C5,4),"0"),LEN(TEXT(DEC2HEX(C5,4),"0"))-3,4),DEC2HEX(C5,4)),1,1),'двоичные коды'!A$1:B$16,2,0),4,1) -> 0 | K5: . | L5: =MID(VLOOKUP(MID(IF(LEN(DEC2HEX(C5,4))>=4,MID(TEXT(DEC2HEX(C5,4),"0"),LEN(TEXT(DEC2HEX(C5,4),"0"))-3,4),DEC2HEX(C5,4)),2,1),'двоичные коды'!A$1:B$16,2,0),1,1) -> 1 | M5: =MID(VLOOKUP(MID(IF(LEN(DEC2HEX(C5,4))>=4,MID(TEXT(DEC2HEX(C5,4),"0"),LEN(TEXT(DEC2HEX(C5,4),"0"))-3,4),DEC2HEX(C5,4)),2,1),'двоичные коды'!A$1:B$16,2,0),2,1) -> 1 | N5: =MID(VLOOKUP(MID(IF(LEN(DEC2HEX(C5,4))>=4,MID(TEXT(DEC2HEX(C5,4),"0"),LEN(TEXT(DEC2HEX(C5,4),"0"))-3,4),DEC2HEX(C5,4)),2,1),'двоичные коды'!A$1:B$16,2,0),3,1) -> 0 | O5: =MID(VLOOKUP(MID(IF(LEN(DEC2HEX(C5,4))>=4,MID(TEXT(DEC2HEX(C5,4),"0"),LEN(TEXT(DEC2HEX(C5,4),"0"))-3,4),DEC2HEX(C5,4)),2,1),'двоичные коды'!A$1:B$16,2,0),4,1) -> 0 | P5: . | Q5: =MID(VLOOKUP(MID(IF(LEN(DEC2HEX(C5,4))>=4,MID(TEXT(DEC2HEX(C5,4),"0"),LEN(TEXT(DEC2HEX(C5,4),"0"))-3,4),DEC2HEX(C5,4)),3,1),'двоичные коды'!A$1:B$16,2,0),1,1) -> 1 | R5: =MID(VLOOKUP(MID(IF(LEN(DEC2HEX(C5,4))>=4,MID(TEXT(DEC2HEX(C5,4),"0"),LEN(TEXT(DEC2HEX(C5,4),"0"))-3,4),DEC2HEX(C5,4)),3,1),'двоичные коды'!A$1:B$16,2,0),2,1) -> 1 | S5: =MID(VLOOKUP(MID(IF(LEN(DEC2HEX(C5,4))>=4,MID(TEXT(DEC2HEX(C5,4),"0"),LEN(TEXT(DEC2HEX(C5,4),"0"))-3,4),DEC2HEX(C5,4)),3,1),'двоичные коды'!A$1:B$16,2,0),3,1) -> 1 | T5: =MID(VLOOKUP(MID(IF(LEN(DEC2HEX(C5,4))>=4,MID(TEXT(DEC2HEX(C5,4),"0"),LEN(TEXT(DEC2HEX(C5,4),"0"))-3,4),DEC2HEX(C5,4)),3,1),'двоичные коды'!A$1:B$16,2,0),4,1) -> 0 | U5: . | V5: =MID(VLOOKUP(MID(IF(LEN(DEC2HEX(C5,4))>=4,MID(TEXT(DEC2HEX(C5,4),"0"),LEN(TEXT(DEC2HEX(C5,4),"0"))-3,4),DEC2HEX(C5,4)),4,1),'двоичные коды'!A$1:B$16,2,0),1,1) -> 1 | W5: =MID(VLOOKUP(MID(IF(LEN(DEC2HEX(C5,4))>=4,MID(TEXT(DEC2HEX(C5,4),"0"),LEN(TEXT(DEC2HEX(C5,4),"0"))-3,4),DEC2HEX(C5,4)),4,1),'двоичные коды'!A$1:B$16,2,0),2,1) -> 0 | X5: =MID(VLOOKUP(MID(IF(LEN(DEC2HEX(C5,4))>=4,MID(TEXT(DEC2HEX(C5,4),"0"),LEN(TEXT(DEC2HEX(C5,4),"0"))-3,4),DEC2HEX(C5,4)),4,1),'двоичные коды'!A$1:B$16,2,0),3,1) -> 1 | Y5: =MID(VLOOKUP(MID(IF(LEN(DEC2HEX(C5,4))>=4,MID(TEXT(DEC2HEX(C5,4),"0"),LEN(TEXT(DEC2HEX(C5,4),"0"))-3,4),DEC2HEX(C5,4)),4,1),'двоичные коды'!A$1:B$16,2,0),4,1) -> 1
A6: X2= | B6: C = | C6: =C3 -> 20458 | E6: B2= | G6: =MID(VLOOKUP(MID(IF(LEN(DEC2HEX(C6,4))>=4,MID(TEXT(DEC2HEX(C6,4),"0"),LEN(TEXT(DEC2HEX(C6,4),"0"))-3,4),DEC2HEX(C6,4)),1,1),'двоичные коды'!A$1:B$16,2,0),1,1) -> 0 | H6: =MID(VLOOKUP(MID(IF(LEN(DEC2HEX(C6,4))>=4,MID(TEXT(DEC2HEX(C6,4),"0"),LEN(TEXT(DEC2HEX(C6,4),"0"))-3,4),DEC2HEX(C6,4)),1,1),'двоичные коды'!A$1:B$16,2,0),2,1) -> 1 | I6: =MID(VLOOKUP(MID(IF(LEN(DEC2HEX(C6,4))>=4,MID(TEXT(DEC2HEX(C6,4),"0"),LEN(TEXT(DEC2HEX(C6,4),"0"))-3,4),DEC2HEX(C6,4)),1,1),'двоичные коды'!A$1:B$16,2,0),3,1) -> 0 | J6: =MID(VLOOKUP(MID(IF(LEN(DEC2HEX(C6,4))>=4,MID(TEXT(DEC2HEX(C6,4),"0"),LEN(TEXT(DEC2HEX(C6,4),"0"))-3,4),DEC2HEX(C6,4)),1,1),'двоичные коды'!A$1:B$16,2,0),4,1) -> 0 | K6: . | L6: =MID(VLOOKUP(MID(IF(LEN(DEC2HEX(C6,4))>=4,MID(TEXT(DEC2HEX(C6,4),"0"),LEN(TEXT(DEC2HEX(C6,4),"0"))-3,4),DEC2HEX(C6,4)),2,1),'двоичные коды'!A$1:B$16,2,0),1,1) -> 1 | M6: =MID(VLOOKUP(MID(IF(LEN(DEC2HEX(C6,4))>=4,MID(TEXT(DEC2HEX(C6,4),"0"),LEN(TEXT(DEC2HEX(C6,4),"0"))-3,4),DEC2HEX(C6,4)),2,1),'двоичные коды'!A$1:B$16,2,0),2,1) -> 1 | N6: =MID(VLOOKUP(MID(IF(LEN(DEC2HEX(C6,4))>=4,MID(TEXT(DEC2HEX(C6,4),"0"),LEN(TEXT(DEC2HEX(C6,4),"0"))-3,4),DEC2HEX(C6,4)),2,1),'двоичные коды'!A$1:B$16,2,0),3,1) -> 1 | O6: =MID(VLOOKUP(MID(IF(LEN(DEC2HEX(C6,4))>=4,MID(TEXT(DEC2HEX(C6,4),"0"),LEN(TEXT(DEC2HEX(C6,4),"0"))-3,4),DEC2HEX(C6,4)),2,1),'двоичные коды'!A$1:B$16,2,0),4,1) -> 1 | P6: . | Q6: =MID(VLOOKUP(MID(IF(LEN(DEC2HEX(C6,4))>=4,MID(TEXT(DEC2HEX(C6,4),"0"),LEN(TEXT(DEC2HEX(C6,4),"0"))-3,4),DEC2HEX(C6,4)),3,1),'двоичные коды'!A$1:B$16,2,0),1,1) -> 1 | R6: =MID(VLOOKUP(MID(IF(LEN(DEC2HEX(C6,4))>=4,MID(TEXT(DEC2HEX(C6,4),"0"),LEN(TEXT(DEC2HEX(C6,4),"0"))-3,4),DEC2HEX(C6,4)),3,1),'двоичные коды'!A$1:B$16,2,0),2,1) -> 1 | S6: =MID(VLOOKUP(MID(IF(LEN(DEC2HEX(C6,4))>=4,MID(TEXT(DEC2HEX(C6,4),"0"),LEN(TEXT(DEC2HEX(C6,4),"0"))-3,4),DEC2HEX(C6,4)),3,1),'двоичные коды'!A$1:B$16,2,0),3,1) -> 1 | T6: =MID(VLOOKUP(MID(IF(LEN(DEC2HEX(C6,4))>=4,MID(TEXT(DEC2HEX(C6,4),"0"),LEN(TEXT(DEC2HEX(C6,4),"0"))-3,4),DEC2HEX(C6,4)),3,1),'двоичные коды'!A$1:B$16,2,0),4,1) -> 0 | U6: . | V6: =MID(VLOOKUP(MID(IF(LEN(DEC2HEX(C6,4))>=4,MID(TEXT(DEC2HEX(C6,4),"0"),LEN(TEXT(DEC2HEX(C6,4),"0"))-3,4),DEC2HEX(C6,4)),4,1),'двоичные коды'!A$1:B$16,2,0),1,1) -> 1 | W6: =MID(VLOOKUP(MID(IF(LEN(DEC2HEX(C6,4))>=4,MID(TEXT(DEC2HEX(C6,4),"0"),LEN(TEXT(DEC2HEX(C6,4),"0"))-3,4),DEC2HEX(C6,4)),4,1),'двоичные коды'!A$1:B$16,2,0),2,1) -> 0 | X6: =MID(VLOOKUP(MID(IF(LEN(DEC2HEX(C6,4))>=4,MID(TEXT(DEC2HEX(C6,4),"0"),LEN(TEXT(DEC2HEX(C6,4),"0"))-3,4),DEC2HEX(C6,4)),4,1),'двоичные коды'!A$1:B$16,2,0),3,1) -> 1 | Y6: =MID(VLOOKUP(MID(IF(LEN(DEC2HEX(C6,4))>=4,MID(TEXT(DEC2HEX(C6,4),"0"),LEN(TEXT(DEC2HEX(C6,4),"0"))-3,4),DEC2HEX(C6,4)),4,1),'двоичные коды'!A$1:B$16,2,0),4,1) -> 0
A7: X3= | B7: A + C = | C7: =C2+C3 -> 23765 | E7: B3= | G7: =MID(VLOOKUP(MID(IF(LEN(DEC2HEX(C7,4))>=4,MID(TEXT(DEC2HEX(C7,4),"0"),LEN(TEXT(DEC2HEX(C7,4),"0"))-3,4),DEC2HEX(C7,4)),1,1),'двоичные коды'!A$1:B$16,2,0),1,1) -> 0 | H7: =MID(VLOOKUP(MID(IF(LEN(DEC2HEX(C7,4))>=4,MID(TEXT(DEC2HEX(C7,4),"0"),LEN(TEXT(DEC2HEX(C7,4),"0"))-3,4),DEC2HEX(C7,4)),1,1),'двоичные коды'!A$1:B$16,2,0),2,1) -> 1 | I7: =MID(VLOOKUP(MID(IF(LEN(DEC2HEX(C7,4))>=4,MID(TEXT(DEC2HEX(C7,4),"0"),LEN(TEXT(DEC2HEX(C7,4),"0"))-3,4),DEC2HEX(C7,4)),1,1),'двоичные коды'!A$1:B$16,2,0),3,1) -> 0 | J7: =MID(VLOOKUP(MID(IF(LEN(DEC2HEX(C7,4))>=4,MID(TEXT(DEC2HEX(C7,4),"0"),LEN(TEXT(DEC2HEX(C7,4),"0"))-3,4),DEC2HEX(C7,4)),1,1),'двоичные коды'!A$1:B$16,2,0),4,1) -> 1 | K7: . | L7: =MID(VLOOKUP(MID(IF(LEN(DEC2HEX(C7,4))>=4,MID(TEXT(DEC2HEX(C7,4),"0"),LEN(TEXT(DEC2HEX(C7,4),"0"))-3,4),DEC2HEX(C7,4)),2,1),'двоичные коды'!A$1:B$16,2,0),1,1) -> 1 | M7: =MID(VLOOKUP(MID(IF(LEN(DEC2HEX(C7,4))>=4,MID(TEXT(DEC2HEX(C7,4),"0"),LEN(TEXT(DEC2HEX(C7,4),"0"))-3,4),DEC2HEX(C7,4)),2,1),'двоичные коды'!A$1:B$16,2,0),2,1) -> 1 | N7: =MID(VLOOKUP(MID(IF(LEN(DEC2HEX(C7,4))>=4,MID(TEXT(DEC2HEX(C7,4),"0"),LEN(TEXT(DEC2HEX(C7,4),"0"))-3,4),DEC2HEX(C7,4)),2,1),'двоичные коды'!A$1:B$16,2,0),3,1) -> 0 | O7: =MID(VLOOKUP(MID(IF(LEN(DEC2HEX(C7,4))>=4,MID(TEXT(DEC2HEX(C7,4),"0"),LEN(TEXT(DEC2HEX(C7,4),"0"))-3,4),DEC2HEX(C7,4)),2,1),'двоичные коды'!A$1:B$16,2,0),4,1) -> 0 | P7: . | Q7: =MID(VLOOKUP(MID(IF(LEN(DEC2HEX(C7,4))>=4,MID(TEXT(DEC2HEX(C7,4),"0"),LEN(TEXT(DEC2HEX(C7,4),"0"))-3,4),DEC2HEX(C7,4)),3,1),'двоичные коды'!A$1:B$16,2,0),1,1) -> 1 | R7: =MID(VLOOKUP(MID(IF(LEN(DEC2HEX(C7,4))>=4,MID(TEXT(DEC2HEX(C7,4),"0"),LEN(TEXT(DEC2HEX(C7,4),"0"))-3,4),DEC2HEX(C7,4)),3,1),'двоичные коды'!A$1:B$16,2,0),2,1) -> 1 | S7: =MID(VLOOKUP(MID(IF(LEN(DEC2HEX(C7,4))>=4,MID(TEXT(DEC2HEX(C7,4),"0"),LEN(TEXT(DEC2HEX(C7,4),"0"))-3,4),DEC2HEX(C7,4)),3,1),'двоичные коды'!A$1:B$16,2,0),3,1) -> 0 | T7: =MID(VLOOKUP(MID(IF(LEN(DEC2HEX(C7,4))>=4,MID(TEXT(DEC2HEX(C7,4),"0"),LEN(TEXT(DEC2HEX(C7,4),"0"))-3,4),DEC2HEX(C7,4)),3,1),'двоичные коды'!A$1:B$16,2,0),4,1) -> 1 | U7: . | V7: =MID(VLOOKUP(MID(IF(LEN(DEC2HEX(C7,4))>=4,MID(TEXT(DEC2HEX(C7,4),"0"),LEN(TEXT(DEC2HEX(C7,4),"0"))-3,4),DEC2HEX(C7,4)),4,1),'двоичные коды'!A$1:B$16,2,0),1,1) -> 0 | W7: =MID(VLOOKUP(MID(IF(LEN(DEC2HEX(C7,4))>=4,MID(TEXT(DEC2HEX(C7,4),"0"),LEN(TEXT(DEC2HEX(C7,4),"0"))-3,4),DEC2HEX(C7,4)),4,1),'двоичные коды'!A$1:B$16,2,0),2,1) -> 1 | X7: =MID(VLOOKUP(MID(IF(LEN(DEC2HEX(C7,4))>=4,MID(TEXT(DEC2HEX(C7,4),"0"),LEN(TEXT(DEC2HEX(C7,4),"0"))-3,4),DEC2HEX(C7,4)),4,1),'двоичные коды'!A$1:B$16,2,0),3,1) -> 0 | Y7: =MID(VLOOKUP(MID(IF(LEN(DEC2HEX(C7,4))>=4,MID(TEXT(DEC2HEX(C7,4),"0"),LEN(TEXT(DEC2HEX(C7,4),"0"))-3,4),DEC2HEX(C7,4)),4,1),'двоичные коды'!A$1:B$16,2,0),4,1) -> 1
A8: X4= | B8: A + C + C = | C8: =C2+C3*2 -> 44223 | E8: B4= | G8: =MID(VLOOKUP(MID(IF(LEN(DEC2HEX(C8,4))>=4,MID(TEXT(DEC2HEX(C8,4),"0"),LEN(TEXT(DEC2HEX(C8,4),"0"))-3,4),DEC2HEX(C8,4)),1,1),'двоичные коды'!A$1:B$16,2,0),1,1) -> 1 | H8: =MID(VLOOKUP(MID(IF(LEN(DEC2HEX(C8,4))>=4,MID(TEXT(DEC2HEX(C8,4),"0"),LEN(TEXT(DEC2HEX(C8,4),"0"))-3,4),DEC2HEX(C8,4)),1,1),'двоичные коды'!A$1:B$16,2,0),2,1) -> 0 | I8: =MID(VLOOKUP(MID(IF(LEN(DEC2HEX(C8,4))>=4,MID(TEXT(DEC2HEX(C8,4),"0"),LEN(TEXT(DEC2HEX(C8,4),"0"))-3,4),DEC2HEX(C8,4)),1,1),'двоичные коды'!A$1:B$16,2,0),3,1) -> 1 | J8: =MID(VLOOKUP(MID(IF(LEN(DEC2HEX(C8,4))>=4,MID(TEXT(DEC2HEX(C8,4),"0"),LEN(TEXT(DEC2HEX(C8,4),"0"))-3,4),DEC2HEX(C8,4)),1,1),'двоичные коды'!A$1:B$16,2,0),4,1) -> 0 | K8: . | L8: =MID(VLOOKUP(MID(IF(LEN(DEC2HEX(C8,4))>=4,MID(TEXT(DEC2HEX(C8,4),"0"),LEN(TEXT(DEC2HEX(C8,4),"0"))-3,4),DEC2HEX(C8,4)),2,1),'двоичные коды'!A$1:B$16,2,0),1,1) -> 1 | M8: =MID(VLOOKUP(MID(IF(LEN(DEC2HEX(C8,4))>=4,MID(TEXT(DEC2HEX(C8,4),"0"),LEN(TEXT(DEC2HEX(C8,4),"0"))-3,4),DEC2HEX(C8,4)),2,1),'двоичные коды'!A$1:B$16,2,0),2,1) -> 1 | N8: =MID(VLOOKUP(MID(IF(LEN(DEC2HEX(C8,4))>=4,MID(TEXT(DEC2HEX(C8,4),"0"),LEN(TEXT(DEC2HEX(C8,4),"0"))-3,4),DEC2HEX(C8,4)),2,1),'двоичные коды'!A$1:B$16,2,0),3,1) -> 0 | O8: =MID(VLOOKUP(MID(IF(LEN(DEC2HEX(C8,4))>=4,MID(TEXT(DEC2HEX(C8,4),"0"),LEN(TEXT(DEC2HEX(C8,4),"0"))-3,4),DEC2HEX(C8,4)),2,1),'двоичные коды'!A$1:B$16,2,0),4,1) -> 0 | P8: . | Q8: =MID(VLOOKUP(MID(IF(LEN(DEC2HEX(C8,4))>=4,MID(TEXT(DEC2HEX(C8,4),"0"),LEN(TEXT(DEC2HEX(C8,4),"0"))-3,4),DEC2HEX(C8,4)),3,1),'двоичные коды'!A$1:B$16,2,0),1,1) -> 1 | R8: =MID(VLOOKUP(MID(IF(LEN(DEC2HEX(C8,4))>=4,MID(TEXT(DEC2HEX(C8,4),"0"),LEN(TEXT(DEC2HEX(C8,4),"0"))-3,4),DEC2HEX(C8,4)),3,1),'двоичные коды'!A$1:B$16,2,0),2,1) -> 0 | S8: =MID(VLOOKUP(MID(IF(LEN(DEC2HEX(C8,4))>=4,MID(TEXT(DEC2HEX(C8,4),"0"),LEN(TEXT(DEC2HEX(C8,4),"0"))-3,4),DEC2HEX(C8,4)),3,1),'двоичные коды'!A$1:B$16,2,0),3,1) -> 1 | T8: =MID(VLOOKUP(MID(IF(LEN(DEC2HEX(C8,4))>=4,MID(TEXT(DEC2HEX(C8,4),"0"),LEN(TEXT(DEC2HEX(C8,4),"0"))-3,4),DEC2HEX(C8,4)),3,1),'двоичные коды'!A$1:B$16,2,0),4,1) -> 1 | U8: . | V8: =MID(VLOOKUP(MID(IF(LEN(DEC2HEX(C8,4))>=4,MID(TEXT(DEC2HEX(C8,4),"0"),LEN(TEXT(DEC2HEX(C8,4),"0"))-3,4),DEC2HEX(C8,4)),4,1),'двоичные коды'!A$1:B$16,2,0),1,1) -> 1 | W8: =MID(VLOOKUP(MID(IF(LEN(DEC2HEX(C8,4))>=4,MID(TEXT(DEC2HEX(C8,4),"0"),LEN(TEXT(DEC2HEX(C8,4),"0"))-3,4),DEC2HEX(C8,4)),4,1),'двоичные коды'!A$1:B$16,2,0),2,1) -> 1 | X8: =MID(VLOOKUP(MID(IF(LEN(DEC2HEX(C8,4))>=4,MID(TEXT(DEC2HEX(C8,4),"0"),LEN(TEXT(DEC2HEX(C8,4),"0"))-3,4),DEC2HEX(C8,4)),4,1),'двоичные коды'!A$1:B$16,2,0),3,1) -> 1 | Y8: =MID(VLOOKUP(MID(IF(LEN(DEC2HEX(C8,4))>=4,MID(TEXT(DEC2HEX(C8,4),"0"),LEN(TEXT(DEC2HEX(C8,4),"0"))-3,4),DEC2HEX(C8,4)),4,1),'двоичные коды'!A$1:B$16,2,0),4,1) -> 1
A9: X5= | B9: C — A = | C9: =C3-C2 -> 17151 | E9: B5= | G9: =MID(VLOOKUP(MID(IF(LEN(DEC2HEX(C9,4))>=4,MID(TEXT(DEC2HEX(C9,4),"0"),LEN(TEXT(DEC2HEX(C9,4),"0"))-3,4),DEC2HEX(C9,4)),1,1),'двоичные коды'!A$1:B$16,2,0),1,1) -> 0 | H9: =MID(VLOOKUP(MID(IF(LEN(DEC2HEX(C9,4))>=4,MID(TEXT(DEC2HEX(C9,4),"0"),LEN(TEXT(DEC2HEX(C9,4),"0"))-3,4),DEC2HEX(C9,4)),1,1),'двоичные коды'!A$1:B$16,2,0),2,1) -> 1 | I9: =MID(VLOOKUP(MID(IF(LEN(DEC2HEX(C9,4))>=4,MID(TEXT(DEC2HEX(C9,4),"0"),LEN(TEXT(DEC2HEX(C9,4),"0"))-3,4),DEC2HEX(C9,4)),1,1),'двоичные коды'!A$1:B$16,2,0),3,1) -> 0 | J9: =MID(VLOOKUP(MID(IF(LEN(DEC2HEX(C9,4))>=4,MID(TEXT(DEC2HEX(C9,4),"0"),LEN(TEXT(DEC2HEX(C9,4),"0"))-3,4),DEC2HEX(C9,4)),1,1),'двоичные коды'!A$1:B$16,2,0),4,1) -> 0 | K9: . | L9: =MID(VLOOKUP(MID(IF(LEN(DEC2HEX(C9,4))>=4,MID(TEXT(DEC2HEX(C9,4),"0"),LEN(TEXT(DEC2HEX(C9,4),"0"))-3,4),DEC2HEX(C9,4)),2,1),'двоичные коды'!A$1:B$16,2,0),1,1) -> 0 | M9: =MID(VLOOKUP(MID(IF(LEN(DEC2HEX(C9,4))>=4,MID(TEXT(DEC2HEX(C9,4),"0"),LEN(TEXT(DEC2HEX(C9,4),"0"))-3,4),DEC2HEX(C9,4)),2,1),'двоичные коды'!A$1:B$16,2,0),2,1) -> 0 | N9: =MID(VLOOKUP(MID(IF(LEN(DEC2HEX(C9,4))>=4,MID(TEXT(DEC2HEX(C9,4),"0"),LEN(TEXT(DEC2HEX(C9,4),"0"))-3,4),DEC2HEX(C9,4)),2,1),'двоичные коды'!A$1:B$16,2,0),3,1) -> 1 | O9: =MID(VLOOKUP(MID(IF(LEN(DEC2HEX(C9,4))>=4,MID(TEXT(DEC2HEX(C9,4),"0"),LEN(TEXT(DEC2HEX(C9,4),"0"))-3,4),DEC2HEX(C9,4)),2,1),'двоичные коды'!A$1:B$16,2,0),4,1) -> 0 | P9: . | Q9: =MID(VLOOKUP(MID(IF(LEN(DEC2HEX(C9,4))>=4,MID(TEXT(DEC2HEX(C9,4),"0"),LEN(TEXT(DEC2HEX(C9,4),"0"))-3,4),DEC2HEX(C9,4)),3,1),'двоичные коды'!A$1:B$16,2,0),1,1) -> 1 | R9: =MID(VLOOKUP(MID(IF(LEN(DEC2HEX(C9,4))>=4,MID(TEXT(DEC2HEX(C9,4),"0"),LEN(TEXT(DEC2HEX(C9,4),"0"))-3,4),DEC2HEX(C9,4)),3,1),'двоичные коды'!A$1:B$16,2,0),2,1) -> 1 | S9: =MID(VLOOKUP(MID(IF(LEN(DEC2HEX(C9,4))>=4,MID(TEXT(DEC2HEX(C9,4),"0"),LEN(TEXT(DEC2HEX(C9,4),"0"))-3,4),DEC2HEX(C9,4)),3,1),'двоичные коды'!A$1:B$16,2,0),3,1) -> 1 | T9: =MID(VLOOKUP(MID(IF(LEN(DEC2HEX(C9,4))>=4,MID(TEXT(DEC2HEX(C9,4),"0"),LEN(TEXT(DEC2HEX(C9,4),"0"))-3,4),DEC2HEX(C9,4)),3,1),'двоичные коды'!A$1:B$16,2,0),4,1) -> 1 | U9: . | V9: =MID(VLOOKUP(MID(IF(LEN(DEC2HEX(C9,4))>=4,MID(TEXT(DEC2HEX(C9,4),"0"),LEN(TEXT(DEC2HEX(C9,4),"0"))-3,4),DEC2HEX(C9,4)),4,1),'двоичные коды'!A$1:B$16,2,0),1,1) -> 1 | W9: =MID(VLOOKUP(MID(IF(LEN(DEC2HEX(C9,4))>=4,MID(TEXT(DEC2HEX(C9,4),"0"),LEN(TEXT(DEC2HEX(C9,4),"0"))-3,4),DEC2HEX(C9,4)),4,1),'двоичные коды'!A$1:B$16,2,0),2,1) -> 1 | X9: =MID(VLOOKUP(MID(IF(LEN(DEC2HEX(C9,4))>=4,MID(TEXT(DEC2HEX(C9,4),"0"),LEN(TEXT(DEC2HEX(C9,4),"0"))-3,4),DEC2HEX(C9,4)),4,1),'двоичные коды'!A$1:B$16,2,0),3,1) -> 1 | Y9: =MID(VLOOKUP(MID(IF(LEN(DEC2HEX(C9,4))>=4,MID(TEXT(DEC2HEX(C9,4),"0"),LEN(TEXT(DEC2HEX(C9,4),"0"))-3,4),DEC2HEX(C9,4)),4,1),'двоичные коды'!A$1:B$16,2,0),4,1) -> 1
A10: X6= | B10: 65536 — X4 = | C10: =65536-C8 -> 21313 | E10: B6= | G10: =MID(VLOOKUP(MID(IF(LEN(DEC2HEX(C10,4))>=4,MID(TEXT(DEC2HEX(C10,4),"0"),LEN(TEXT(DEC2HEX(C10,4),"0"))-3,4),DEC2HEX(C10,4)),1,1),'двоичные коды'!A$1:B$16,2,0),1,1) -> 0 | H10: =MID(VLOOKUP(MID(IF(LEN(DEC2HEX(C10,4))>=4,MID(TEXT(DEC2HEX(C10,4),"0"),LEN(TEXT(DEC2HEX(C10,4),"0"))-3,4),DEC2HEX(C10,4)),1,1),'двоичные коды'!A$1:B$16,2,0),2,1) -> 1 | I10: =MID(VLOOKUP(MID(IF(LEN(DEC2HEX(C10,4))>=4,MID(TEXT(DEC2HEX(C10,4),"0"),LEN(TEXT(DEC2HEX(C10,4),"0"))-3,4),DEC2HEX(C10,4)),1,1),'двоичные коды'!A$1:B$16,2,0),3,1) -> 0 | J10: =MID(VLOOKUP(MID(IF(LEN(DEC2HEX(C10,4))>=4,MID(TEXT(DEC2HEX(C10,4),"0"),LEN(TEXT(DEC2HEX(C10,4),"0"))-3,4),DEC2HEX(C10,4)),1,1),'двоичные коды'!A$1:B$16,2,0),4,1) -> 1 | K10: . | L10: =MID(VLOOKUP(MID(IF(LEN(DEC2HEX(C10,4))>=4,MID(TEXT(DEC2HEX(C10,4),"0"),LEN(TEXT(DEC2HEX(C10,4),"0"))-3,4),DEC2HEX(C10,4)),2,1),'двоичные коды'!A$1:B$16,2,0),1,1) -> 0 | M10: =MID(VLOOKUP(MID(IF(LEN(DEC2HEX(C10,4))>=4,MID(TEXT(DEC2HEX(C10,4),"0"),LEN(TEXT(DEC2HEX(C10,4),"0"))-3,4),DEC2HEX(C10,4)),2,1),'двоичные коды'!A$1:B$16,2,0),2,1) -> 0 | N10: =MID(VLOOKUP(MID(IF(LEN(DEC2HEX(C10,4))>=4,MID(TEXT(DEC2HEX(C10,4),"0"),LEN(TEXT(DEC2HEX(C10,4),"0"))-3,4),DEC2HEX(C10,4)),2,1),'двоичные коды'!A$1:B$16,2,0),3,1) -> 1 | O10: =MID(VLOOKUP(MID(IF(LEN(DEC2HEX(C10,4))>=4,MID(TEXT(DEC2HEX(C10,4),"0"),LEN(TEXT(DEC2HEX(C10,4),"0"))-3,4),DEC2HEX(C10,4)),2,1),'двоичные коды'!A$1:B$16,2,0),4,1) -> 1 | P10: . | Q10: =MID(VLOOKUP(MID(IF(LEN(DEC2HEX(C10,4))>=4,MID(TEXT(DEC2HEX(C10,4),"0"),LEN(TEXT(DEC2HEX(C10,4),"0"))-3,4),DEC2HEX(C10,4)),3,1),'двоичные коды'!A$1:B$16,2,0),1,1) -> 0 | R10: =MID(VLOOKUP(MID(IF(LEN(DEC2HEX(C10,4))>=4,MID(TEXT(DEC2HEX(C10,4),"0"),LEN(TEXT(DEC2HEX(C10,4),"0"))-3,4),DEC2HEX(C10,4)),3,1),'двоичные коды'!A$1:B$16,2,0),2,1) -> 1 | S10: =MID(VLOOKUP(MID(IF(LEN(DEC2HEX(C10,4))>=4,MID(TEXT(DEC2HEX(C10,4),"0"),LEN(TEXT(DEC2HEX(C10,4),"0"))-3,4),DEC2HEX(C10,4)),3,1),'двоичные коды'!A$1:B$16,2,0),3,1) -> 0 | T10: =MID(VLOOKUP(MID(IF(LEN(DEC2HEX(C10,4))>=4,MID(TEXT(DEC2HEX(C10,4),"0"),LEN(TEXT(DEC2HEX(C10,4),"0"))-3,4),DEC2HEX(C10,4)),3,1),'двоичные коды'!A$1:B$16,2,0),4,1) -> 0 | U10: . | V10: =MID(VLOOKUP(MID(IF(LEN(DEC2HEX(C10,4))>=4,MID(TEXT(DEC2HEX(C10,4),"0"),LEN(TEXT(DEC2HEX(C10,4),"0"))-3,4),DEC2HEX(C10,4)),4,1),'двоичные коды'!A$1:B$16,2,0),1,1) -> 0 | W10: =MID(VLOOKUP(MID(IF(LEN(DEC2HEX(C10,4))>=4,MID(TEXT(DEC2HEX(C10,4),"0"),LEN(TEXT(DEC2HEX(C10,4),"0"))-3,4),DEC2HEX(C10,4)),4,1),'двоичные коды'!A$1:B$16,2,0),2,1) -> 0 | X10: =MID(VLOOKUP(MID(IF(LEN(DEC2HEX(C10,4))>=4,MID(TEXT(DEC2HEX(C10,4),"0"),LEN(TEXT(DEC2HEX(C10,4),"0"))-3,4),DEC2HEX(C10,4)),4,1),'двоичные коды'!A$1:B$16,2,0),3,1) -> 0 | Y10: =MID(VLOOKUP(MID(IF(LEN(DEC2HEX(C10,4))>=4,MID(TEXT(DEC2HEX(C10,4),"0"),LEN(TEXT(DEC2HEX(C10,4),"0"))-3,4),DEC2HEX(C10,4)),4,1),'двоичные коды'!A$1:B$16,2,0),4,1) -> 1
A11: X7= | B11: -X1 = | C11: =-C5 -> -3307 | E11: B7= | F11: -B1= | G11: =MID(VLOOKUP(MID(IF(LEN(DEC2HEX(C11,4))>=4,MID(TEXT(DEC2HEX(C11,4),"0"),LEN(TEXT(DEC2HEX(C11,4),"0"))-3,4),DEC2HEX(C11,4)),1,1),'двоичные коды'!A$1:B$16,2,0),1,1) -> 1 | H11: =MID(VLOOKUP(MID(IF(LEN(DEC2HEX(C11,4))>=4,MID(TEXT(DEC2HEX(C11,4),"0"),LEN(TEXT(DEC2HEX(C11,4),"0"))-3,4),DEC2HEX(C11,4)),1,1),'двоичные коды'!A$1:B$16,2,0),2,1) -> 1 | I11: =MID(VLOOKUP(MID(IF(LEN(DEC2HEX(C11,4))>=4,MID(TEXT(DEC2HEX(C11,4),"0"),LEN(TEXT(DEC2HEX(C11,4),"0"))-3,4),DEC2HEX(C11,4)),1,1),'двоичные коды'!A$1:B$16,2,0),3,1) -> 1 | J11: =MID(VLOOKUP(MID(IF(LEN(DEC2HEX(C11,4))>=4,MID(TEXT(DEC2HEX(C11,4),"0"),LEN(TEXT(DEC2HEX(C11,4),"0"))-3,4),DEC2HEX(C11,4)),1,1),'двоичные коды'!A$1:B$16,2,0),4,1) -> 1 | K11: . | L11: =MID(VLOOKUP(MID(IF(LEN(DEC2HEX(C11,4))>=4,MID(TEXT(DEC2HEX(C11,4),"0"),LEN(TEXT(DEC2HEX(C11,4),"0"))-3,4),DEC2HEX(C11,4)),2,1),'двоичные коды'!A$1:B$16,2,0),1,1) -> 0 | M11: =MID(VLOOKUP(MID(IF(LEN(DEC2HEX(C11,4))>=4,MID(TEXT(DEC2HEX(C11,4),"0"),LEN(TEXT(DEC2HEX(C11,4),"0"))-3,4),DEC2HEX(C11,4)),2,1),'двоичные коды'!A$1:B$16,2,0),2,1) -> 0 | N11: =MID(VLOOKUP(MID(IF(LEN(DEC2HEX(C11,4))>=4,MID(TEXT(DEC2HEX(C11,4),"0"),LEN(TEXT(DEC2HEX(C11,4),"0"))-3,4),DEC2HEX(C11,4)),2,1),'двоичные коды'!A$1:B$16,2,0),3,1) -> 1 | O11: =MID(VLOOKUP(MID(IF(LEN(DEC2HEX(C11,4))>=4,MID(TEXT(DEC2HEX(C11,4),"0"),LEN(TEXT(DEC2HEX(C11,4),"0"))-3,4),DEC2HEX(C11,4)),2,1),'двоичные коды'!A$1:B$16,2,0),4,1) -> 1 | P11: . | Q11: =MID(VLOOKUP(MID(IF(LEN(DEC2HEX(C11,4))>=4,MID(TEXT(DEC2HEX(C11,4),"0"),LEN(TEXT(DEC2HEX(C11,4),"0"))-3,4),DEC2HEX(C11,4)),3,1),'двоичные коды'!A$1:B$16,2,0),1,1) -> 0 | R11: =MID(VLOOKUP(MID(IF(LEN(DEC2HEX(C11,4))>=4,MID(TEXT(DEC2HEX(C11,4),"0"),LEN(TEXT(DEC2HEX(C11,4),"0"))-3,4),DEC2HEX(C11,4)),3,1),'двоичные коды'!A$1:B$16,2,0),2,1) -> 0 | S11: =MID(VLOOKUP(MID(IF(LEN(DEC2HEX(C11,4))>=4,MID(TEXT(DEC2HEX(C11,4),"0"),LEN(TEXT(DEC2HEX(C11,4),"0"))-3,4),DEC2HEX(C11,4)),3,1),'двоичные коды'!A$1:B$16,2,0),3,1) -> 0 | T11: =MID(VLOOKUP(MID(IF(LEN(DEC2HEX(C11,4))>=4,MID(TEXT(DEC2HEX(C11,4),"0"),LEN(TEXT(DEC2HEX(C11,4),"0"))-3,4),DEC2HEX(C11,4)),3,1),'двоичные коды'!A$1:B$16,2,0),4,1) -> 1 | U11: . | V11: =MID(VLOOKUP(MID(IF(LEN(DEC2HEX(C11,4))>=4,MID(TEXT(DEC2HEX(C11,4),"0"),LEN(TEXT(DEC2HEX(C11,4),"0"))-3,4),DEC2HEX(C11,4)),4,1),'двоичные коды'!A$1:B$16,2,0),1,1) -> 0 | W11: =MID(VLOOKUP(MID(IF(LEN(DEC2HEX(C11,4))>=4,MID(TEXT(DEC2HEX(C11,4),"0"),LEN(TEXT(DEC2HEX(C11,4),"0"))-3,4),DEC2HEX(C11,4)),4,1),'двоичные коды'!A$1:B$16,2,0),2,1) -> 1 | X11: =MID(VLOOKUP(MID(IF(LEN(DEC2HEX(C11,4))>=4,MID(TEXT(DEC2HEX(C11,4),"0"),LEN(TEXT(DEC2HEX(C11,4),"0"))-3,4),DEC2HEX(C11,4)),4,1),'двоичные коды'!A$1:B$16,2,0),3,1) -> 0 | Y11: =MID(VLOOKUP(MID(IF(LEN(DEC2HEX(C11,4))>=4,MID(TEXT(DEC2HEX(C11,4),"0"),LEN(TEXT(DEC2HEX(C11,4),"0"))-3,4),DEC2HEX(C11,4)),4,1),'двоичные коды'!A$1:B$16,2,0),4,1) -> 1
A12: X8= | B12: -X2 = | C12: =-C6 -> -20458 | E12: B8= | F12: -B2= | G12: =MID(VLOOKUP(MID(IF(LEN(DEC2HEX(C12,4))>=4,MID(TEXT(DEC2HEX(C12,4),"0"),LEN(TEXT(DEC2HEX(C12,4),"0"))-3,4),DEC2HEX(C12,4)),1,1),'двоичные коды'!A$1:B$16,2,0),1,1) -> 1 | H12: =MID(VLOOKUP(MID(IF(LEN(DEC2HEX(C12,4))>=4,MID(TEXT(DEC2HEX(C12,4),"0"),LEN(TEXT(DEC2HEX(C12,4),"0"))-3,4),DEC2HEX(C12,4)),1,1),'двоичные коды'!A$1:B$16,2,0),2,1) -> 0 | I12: =MID(VLOOKUP(MID(IF(LEN(DEC2HEX(C12,4))>=4,MID(TEXT(DEC2HEX(C12,4),"0"),LEN(TEXT(DEC2HEX(C12,4),"0"))-3,4),DEC2HEX(C12,4)),1,1),'двоичные коды'!A$1:B$16,2,0),3,1) -> 1 | J12: =MID(VLOOKUP(MID(IF(LEN(DEC2HEX(C12,4))>=4,MID(TEXT(DEC2HEX(C12,4),"0"),LEN(TEXT(DEC2HEX(C12,4),"0"))-3,4),DEC2HEX(C12,4)),1,1),'двоичные коды'!A$1:B$16,2,0),4,1) -> 1 | K12: . | L12: =MID(VLOOKUP(MID(IF(LEN(DEC2HEX(C12,4))>=4,MID(TEXT(DEC2HEX(C12,4),"0"),LEN(TEXT(DEC2HEX(C12,4),"0"))-3,4),DEC2HEX(C12,4)),2,1),'двоичные коды'!A$1:B$16,2,0),1,1) -> 0 | M12: =MID(VLOOKUP(MID(IF(LEN(DEC2HEX(C12,4))>=4,MID(TEXT(DEC2HEX(C12,4),"0"),LEN(TEXT(DEC2HEX(C12,4),"0"))-3,4),DEC2HEX(C12,4)),2,1),'двоичные коды'!A$1:B$16,2,0),2,1) -> 0 | N12: =MID(VLOOKUP(MID(IF(LEN(DEC2HEX(C12,4))>=4,MID(TEXT(DEC2HEX(C12,4),"0"),LEN(TEXT(DEC2HEX(C12,4),"0"))-3,4),DEC2HEX(C12,4)),2,1),'двоичные коды'!A$1:B$16,2,0),3,1) -> 0 | O12: =MID(VLOOKUP(MID(IF(LEN(DEC2HEX(C12,4))>=4,MID(TEXT(DEC2HEX(C12,4),"0"),LEN(TEXT(DEC2HEX(C12,4),"0"))-3,4),DEC2HEX(C12,4)),2,1),'двоичные коды'!A$1:B$16,2,0),4,1) -> 0 | P12: . | Q12: =MID(VLOOKUP(MID(IF(LEN(DEC2HEX(C12,4))>=4,MID(TEXT(DEC2HEX(C12,4),"0"),LEN(TEXT(DEC2HEX(C12,4),"0"))-3,4),DEC2HEX(C12,4)),3,1),'двоичные коды'!A$1:B$16,2,0),1,1) -> 0 | R12: =MID(VLOOKUP(MID(IF(LEN(DEC2HEX(C12,4))>=4,MID(TEXT(DEC2HEX(C12,4),"0"),LEN(TEXT(DEC2HEX(C12,4),"0"))-3,4),DEC2HEX(C12,4)),3,1),'двоичные коды'!A$1:B$16,2,0),2,1) -> 0 | S12: =MID(VLOOKUP(MID(IF(LEN(DEC2HEX(C12,4))>=4,MID(TEXT(DEC2HEX(C12,4),"0"),LEN(TEXT(DEC2HEX(C12,4),"0"))-3,4),DEC2HEX(C12,4)),3,1),'двоичные коды'!A$1:B$16,2,0),3,1) -> 0 | T12: =MID(VLOOKUP(MID(IF(LEN(DEC2HEX(C12,4))>=4,MID(TEXT(DEC2HEX(C12,4),"0"),LEN(TEXT(DEC2HEX(C12,4),"0"))-3,4),DEC2HEX(C12,4)),3,1),'двоичные коды'!A$1:B$16,2,0),4,1) -> 1 | U12: . | V12: =MID(VLOOKUP(MID(IF(LEN(DEC2HEX(C12,4))>=4,MID(TEXT(DEC2HEX(C12,4),"0"),LEN(TEXT(DEC2HEX(C12,4),"0"))-3,4),DEC2HEX(C12,4)),4,1),'двоичные коды'!A$1:B$16,2,0),1,1) -> 0 | W12: =MID(VLOOKUP(MID(IF(LEN(DEC2HEX(C12,4))>=4,MID(TEXT(DEC2HEX(C12,4),"0"),LEN(TEXT(DEC2HEX(C12,4),"0"))-3,4),DEC2HEX(C12,4)),4,1),'двоичные коды'!A$1:B$16,2,0),2,1) -> 1 | X12: =MID(VLOOKUP(MID(IF(LEN(DEC2HEX(C12,4))>=4,MID(TEXT(DEC2HEX(C12,4),"0"),LEN(TEXT(DEC2HEX(C12,4),"0"))-3,4),DEC2HEX(C12,4)),4,1),'двоичные коды'!A$1:B$16,2,0),3,1) -> 1 | Y12: =MID(VLOOKUP(MID(IF(LEN(DEC2HEX(C12,4))>=4,MID(TEXT(DEC2HEX(C12,4),"0"),LEN(TEXT(DEC2HEX(C12,4),"0"))-3,4),DEC2HEX(C12,4)),4,1),'двоичные коды'!A$1:B$16,2,0),4,1) -> 0
A13: X9= | B13: -X3= | C13: =-C7 -> -23765 | E13: B9= | F13: -B3= | G13: =MID(VLOOKUP(MID(IF(LEN(DEC2HEX(C13,4))>=4,MID(TEXT(DEC2HEX(C13,4),"0"),LEN(TEXT(DEC2HEX(C13,4),"0"))-3,4),DEC2HEX(C13,4)),1,1),'двоичные коды'!A$1:B$16,2,0),1,1) -> 1 | H13: =MID(VLOOKUP(MID(IF(LEN(DEC2HEX(C13,4))>=4,MID(TEXT(DEC2HEX(C13,4),"0"),LEN(TEXT(DEC2HEX(C13,4),"0"))-3,4),DEC2HEX(C13,4)),1,1),'двоичные коды'!A$1:B$16,2,0),2,1) -> 0 | I13: =MID(VLOOKUP(MID(IF(LEN(DEC2HEX(C13,4))>=4,MID(TEXT(DEC2HEX(C13,4),"0"),LEN(TEXT(DEC2HEX(C13,4),"0"))-3,4),DEC2HEX(C13,4)),1,1),'двоичные коды'!A$1:B$16,2,0),3,1) -> 1 | J13: =MID(VLOOKUP(MID(IF(LEN(DEC2HEX(C13,4))>=4,MID(TEXT(DEC2HEX(C13,4),"0"),LEN(TEXT(DEC2HEX(C13,4),"0"))-3,4),DEC2HEX(C13,4)),1,1),'двоичные коды'!A$1:B$16,2,0),4,1) -> 0 | K13: . | L13: =MID(VLOOKUP(MID(IF(LEN(DEC2HEX(C13,4))>=4,MID(TEXT(DEC2HEX(C13,4),"0"),LEN(TEXT(DEC2HEX(C13,4),"0"))-3,4),DEC2HEX(C13,4)),2,1),'двоичные коды'!A$1:B$16,2,0),1,1) -> 0 | M13: =MID(VLOOKUP(MID(IF(LEN(DEC2HEX(C13,4))>=4,MID(TEXT(DEC2HEX(C13,4),"0"),LEN(TEXT(DEC2HEX(C13,4),"0"))-3,4),DEC2HEX(C13,4)),2,1),'двоичные коды'!A$1:B$16,2,0),2,1) -> 0 | N13: =MID(VLOOKUP(MID(IF(LEN(DEC2HEX(C13,4))>=4,MID(TEXT(DEC2HEX(C13,4),"0"),LEN(TEXT(DEC2HEX(C13,4),"0"))-3,4),DEC2HEX(C13,4)),2,1),'двоичные коды'!A$1:B$16,2,0),3,1) -> 1 | O13: =MID(VLOOKUP(MID(IF(LEN(DEC2HEX(C13,4))>=4,MID(TEXT(DEC2HEX(C13,4),"0"),LEN(TEXT(DEC2HEX(C13,4),"0"))-3,4),DEC2HEX(C13,4)),2,1),'двоичные коды'!A$1:B$16,2,0),4,1) -> 1 | P13: . | Q13: =MID(VLOOKUP(MID(IF(LEN(DEC2HEX(C13,4))>=4,MID(TEXT(DEC2HEX(C13,4),"0"),LEN(TEXT(DEC2HEX(C13,4),"0"))-3,4),DEC2HEX(C13,4)),3,1),'двоичные коды'!A$1:B$16,2,0),1,1) -> 0 | R13: =MID(VLOOKUP(MID(IF(LEN(DEC2HEX(C13,4))>=4,MID(TEXT(DEC2HEX(C13,4),"0"),LEN(TEXT(DEC2HEX(C13,4),"0"))-3,4),DEC2HEX(C13,4)),3,1),'двоичные коды'!A$1:B$16,2,0),2,1) -> 0 | S13: =MID(VLOOKUP(MID(IF(LEN(DEC2HEX(C13,4))>=4,MID(TEXT(DEC2HEX(C13,4),"0"),LEN(TEXT(DEC2HEX(C13,4),"0"))-3,4),DEC2HEX(C13,4)),3,1),'двоичные коды'!A$1:B$16,2,0),3,1) -> 1 | T13: =MID(VLOOKUP(MID(IF(LEN(DEC2HEX(C13,4))>=4,MID(TEXT(DEC2HEX(C13,4),"0"),LEN(TEXT(DEC2HEX(C13,4),"0"))-3,4),DEC2HEX(C13,4)),3,1),'двоичные коды'!A$1:B$16,2,0),4,1) -> 0 | U13: . | V13: =MID(VLOOKUP(MID(IF(LEN(DEC2HEX(C13,4))>=4,MID(TEXT(DEC2HEX(C13,4),"0"),LEN(TEXT(DEC2HEX(C13,4),"0"))-3,4),DEC2HEX(C13,4)),4,1),'двоичные коды'!A$1:B$16,2,0),1,1) -> 1 | W13: =MID(VLOOKUP(MID(IF(LEN(DEC2HEX(C13,4))>=4,MID(TEXT(DEC2HEX(C13,4),"0"),LEN(TEXT(DEC2HEX(C13,4),"0"))-3,4),DEC2HEX(C13,4)),4,1),'двоичные коды'!A$1:B$16,2,0),2,1) -> 0 | X13: =MID(VLOOKUP(MID(IF(LEN(DEC2HEX(C13,4))>=4,MID(TEXT(DEC2HEX(C13,4),"0"),LEN(TEXT(DEC2HEX(C13,4),"0"))-3,4),DEC2HEX(C13,4)),4,1),'двоичные коды'!A$1:B$16,2,0),3,1) -> 1 | Y13: =MID(VLOOKUP(MID(IF(LEN(DEC2HEX(C13,4))>=4,MID(TEXT(DEC2HEX(C13,4),"0"),LEN(TEXT(DEC2HEX(C13,4),"0"))-3,4),DEC2HEX(C13,4)),4,1),'двоичные коды'!A$1:B$16,2,0),4,1) -> 1
A14: X10= | B14: -X4= | C14: =-C8 -> -44223 | E14: B10= | F14: -B4= | G14: =MID(VLOOKUP(MID(IF(LEN(DEC2HEX(C14,4))>=4,MID(TEXT(DEC2HEX(C14,4),"0"),LEN(TEXT(DEC2HEX(C14,4),"0"))-3,4),DEC2HEX(C14,4)),1,1),'двоичные коды'!A$1:B$16,2,0),1,1) -> 0 | H14: =MID(VLOOKUP(MID(IF(LEN(DEC2HEX(C14,4))>=4,MID(TEXT(DEC2HEX(C14,4),"0"),LEN(TEXT(DEC2HEX(C14,4),"0"))-3,4),DEC2HEX(C14,4)),1,1),'двоичные коды'!A$1:B$16,2,0),2,1) -> 1 | I14: =MID(VLOOKUP(MID(IF(LEN(DEC2HEX(C14,4))>=4,MID(TEXT(DEC2HEX(C14,4),"0"),LEN(TEXT(DEC2HEX(C14,4),"0"))-3,4),DEC2HEX(C14,4)),1,1),'двоичные коды'!A$1:B$16,2,0),3,1) -> 0 | J14: =MID(VLOOKUP(MID(IF(LEN(DEC2HEX(C14,4))>=4,MID(TEXT(DEC2HEX(C14,4),"0"),LEN(TEXT(DEC2HEX(C14,4),"0"))-3,4),DEC2HEX(C14,4)),1,1),'двоичные коды'!A$1:B$16,2,0),4,1) -> 1 | K14: . | L14: =MID(VLOOKUP(MID(IF(LEN(DEC2HEX(C14,4))>=4,MID(TEXT(DEC2HEX(C14,4),"0"),LEN(TEXT(DEC2HEX(C14,4),"0"))-3,4),DEC2HEX(C14,4)),2,1),'двоичные коды'!A$1:B$16,2,0),1,1) -> 0 | M14: =MID(VLOOKUP(MID(IF(LEN(DEC2HEX(C14,4))>=4,MID(TEXT(DEC2HEX(C14,4),"0"),LEN(TEXT(DEC2HEX(C14,4),"0"))-3,4),DEC2HEX(C14,4)),2,1),'двоичные коды'!A$1:B$16,2,0),2,1) -> 0 | N14: =MID(VLOOKUP(MID(IF(LEN(DEC2HEX(C14,4))>=4,MID(TEXT(DEC2HEX(C14,4),"0"),LEN(TEXT(DEC2HEX(C14,4),"0"))-3,4),DEC2HEX(C14,4)),2,1),'двоичные коды'!A$1:B$16,2,0),3,1) -> 1 | O14: =MID(VLOOKUP(MID(IF(LEN(DEC2HEX(C14,4))>=4,MID(TEXT(DEC2HEX(C14,4),"0"),LEN(TEXT(DEC2HEX(C14,4),"0"))-3,4),DEC2HEX(C14,4)),2,1),'двоичные коды'!A$1:B$16,2,0),4,1) -> 1 | P14: . | Q14: =MID(VLOOKUP(MID(IF(LEN(DEC2HEX(C14,4))>=4,MID(TEXT(DEC2HEX(C14,4),"0"),LEN(TEXT(DEC2HEX(C14,4),"0"))-3,4),DEC2HEX(C14,4)),3,1),'двоичные коды'!A$1:B$16,2,0),1,1) -> 0 | R14: =MID(VLOOKUP(MID(IF(LEN(DEC2HEX(C14,4))>=4,MID(TEXT(DEC2HEX(C14,4),"0"),LEN(TEXT(DEC2HEX(C14,4),"0"))-3,4),DEC2HEX(C14,4)),3,1),'двоичные коды'!A$1:B$16,2,0),2,1) -> 1 | S14: =MID(VLOOKUP(MID(IF(LEN(DEC2HEX(C14,4))>=4,MID(TEXT(DEC2HEX(C14,4),"0"),LEN(TEXT(DEC2HEX(C14,4),"0"))-3,4),DEC2HEX(C14,4)),3,1),'двоичные коды'!A$1:B$16,2,0),3,1) -> 0 | T14: =MID(VLOOKUP(MID(IF(LEN(DEC2HEX(C14,4))>=4,MID(TEXT(DEC2HEX(C14,4),"0"),LEN(TEXT(DEC2HEX(C14,4),"0"))-3,4),DEC2HEX(C14,4)),3,1),'двоичные коды'!A$1:B$16,2,0),4,1) -> 0 | U14: . | V14: =MID(VLOOKUP(MID(IF(LEN(DEC2HEX(C14,4))>=4,MID(TEXT(DEC2HEX(C14,4),"0"),LEN(TEXT(DEC2HEX(C14,4),"0"))-3,4),DEC2HEX(C14,4)),4,1),'двоичные коды'!A$1:B$16,2,0),1,1) -> 0 | W14: =MID(VLOOKUP(MID(IF(LEN(DEC2HEX(C14,4))>=4,MID(TEXT(DEC2HEX(C14,4),"0"),LEN(TEXT(DEC2HEX(C14,4),"0"))-3,4),DEC2HEX(C14,4)),4,1),'двоичные коды'!A$1:B$16,2,0),2,1) -> 0 | X14: =MID(VLOOKUP(MID(IF(LEN(DEC2HEX(C14,4))>=4,MID(TEXT(DEC2HEX(C14,4),"0"),LEN(TEXT(DEC2HEX(C14,4),"0"))-3,4),DEC2HEX(C14,4)),4,1),'двоичные коды'!A$1:B$16,2,0),3,1) -> 0 | Y14: =MID(VLOOKUP(MID(IF(LEN(DEC2HEX(C14,4))>=4,MID(TEXT(DEC2HEX(C14,4),"0"),LEN(TEXT(DEC2HEX(C14,4),"0"))-3,4),DEC2HEX(C14,4)),4,1),'двоичные коды'!A$1:B$16,2,0),4,1) -> 1
A15: X11= | B15: -X5= | C15: =-C9 -> -17151 | E15: B11= | F15: -B5= | G15: =MID(VLOOKUP(MID(IF(LEN(DEC2HEX(C15,4))>=4,MID(TEXT(DEC2HEX(C15,4),"0"),LEN(TEXT(DEC2HEX(C15,4),"0"))-3,4),DEC2HEX(C15,4)),1,1),'двоичные коды'!A$1:B$16,2,0),1,1) -> 1 | H15: =MID(VLOOKUP(MID(IF(LEN(DEC2HEX(C15,4))>=4,MID(TEXT(DEC2HEX(C15,4),"0"),LEN(TEXT(DEC2HEX(C15,4),"0"))-3,4),DEC2HEX(C15,4)),1,1),'двоичные коды'!A$1:B$16,2,0),2,1) -> 0 | I15: =MID(VLOOKUP(MID(IF(LEN(DEC2HEX(C15,4))>=4,MID(TEXT(DEC2HEX(C15,4),"0"),LEN(TEXT(DEC2HEX(C15,4),"0"))-3,4),DEC2HEX(C15,4)),1,1),'двоичные коды'!A$1:B$16,2,0),3,1) -> 1 | J15: =MID(VLOOKUP(MID(IF(LEN(DEC2HEX(C15,4))>=4,MID(TEXT(DEC2HEX(C15,4),"0"),LEN(TEXT(DEC2HEX(C15,4),"0"))-3,4),DEC2HEX(C15,4)),1,1),'двоичные коды'!A$1:B$16,2,0),4,1) -> 1 | K15: . | L15: =MID(VLOOKUP(MID(IF(LEN(DEC2HEX(C15,4))>=4,MID(TEXT(DEC2HEX(C15,4),"0"),LEN(TEXT(DEC2HEX(C15,4),"0"))-3,4),DEC2HEX(C15,4)),2,1),'двоичные коды'!A$1:B$16,2,0),1,1) -> 1 | M15: =MID(VLOOKUP(MID(IF(LEN(DEC2HEX(C15,4))>=4,MID(TEXT(DEC2HEX(C15,4),"0"),LEN(TEXT(DEC2HEX(C15,4),"0"))-3,4),DEC2HEX(C15,4)),2,1),'двоичные коды'!A$1:B$16,2,0),2,1) -> 1 | N15: =MID(VLOOKUP(MID(IF(LEN(DEC2HEX(C15,4))>=4,MID(TEXT(DEC2HEX(C15,4),"0"),LEN(TEXT(DEC2HEX(C15,4),"0"))-3,4),DEC2HEX(C15,4)),2,1),'двоичные коды'!A$1:B$16,2,0),3,1) -> 0 | O15: =MID(VLOOKUP(MID(IF(LEN(DEC2HEX(C15,4))>=4,MID(TEXT(DEC2HEX(C15,4),"0"),LEN(TEXT(DEC2HEX(C15,4),"0"))-3,4),DEC2HEX(C15,4)),2,1),'двоичные коды'!A$1:B$16,2,0),4,1) -> 1 | P15: . | Q15: =MID(VLOOKUP(MID(IF(LEN(DEC2HEX(C15,4))>=4,MID(TEXT(DEC2HEX(C15,4),"0"),LEN(TEXT(DEC2HEX(C15,4),"0"))-3,4),DEC2HEX(C15,4)),3,1),'двоичные коды'!A$1:B$16,2,0),1,1) -> 0 | R15: =MID(VLOOKUP(MID(IF(LEN(DEC2HEX(C15,4))>=4,MID(TEXT(DEC2HEX(C15,4),"0"),LEN(TEXT(DEC2HEX(C15,4),"0"))-3,4),DEC2HEX(C15,4)),3,1),'двоичные коды'!A$1:B$16,2,0),2,1) -> 0 | S15: =MID(VLOOKUP(MID(IF(LEN(DEC2HEX(C15,4))>=4,MID(TEXT(DEC2HEX(C15,4),"0"),LEN(TEXT(DEC2HEX(C15,4),"0"))-3,4),DEC2HEX(C15,4)),3,1),'двоичные коды'!A$1:B$16,2,0),3,1) -> 0 | T15: =MID(VLOOKUP(MID(IF(LEN(DEC2HEX(C15,4))>=4,MID(TEXT(DEC2HEX(C15,4),"0"),LEN(TEXT(DEC2HEX(C15,4),"0"))-3,4),DEC2HEX(C15,4)),3,1),'двоичные коды'!A$1:B$16,2,0),4,1) -> 0 | U15: . | V15: =MID(VLOOKUP(MID(IF(LEN(DEC2HEX(C15,4))>=4,MID(TEXT(DEC2HEX(C15,4),"0"),LEN(TEXT(DEC2HEX(C15,4),"0"))-3,4),DEC2HEX(C15,4)),4,1),'двоичные коды'!A$1:B$16,2,0),1,1) -> 0 | W15: =MID(VLOOKUP(MID(IF(LEN(DEC2HEX(C15,4))>=4,MID(TEXT(DEC2HEX(C15,4),"0"),LEN(TEXT(DEC2HEX(C15,4),"0"))-3,4),DEC2HEX(C15,4)),4,1),'двоичные коды'!A$1:B$16,2,0),2,1) -> 0 | X15: =MID(VLOOKUP(MID(IF(LEN(DEC2HEX(C15,4))>=4,MID(TEXT(DEC2HEX(C15,4),"0"),LEN(TEXT(DEC2HEX(C15,4),"0"))-3,4),DEC2HEX(C15,4)),4,1),'двоичные коды'!A$1:B$16,2,0),3,1) -> 0 | Y15: =MID(VLOOKUP(MID(IF(LEN(DEC2HEX(C15,4))>=4,MID(TEXT(DEC2HEX(C15,4),"0"),LEN(TEXT(DEC2HEX(C15,4),"0"))-3,4),DEC2HEX(C15,4)),4,1),'двоичные коды'!A$1:B$16,2,0),4,1) -> 1
A16: X12= | B16: -X6= | C16: =-C10 -> -21313 | E16: B12= | F16: -B6= | G16: =MID(VLOOKUP(MID(IF(LEN(DEC2HEX(C16,4))>=4,MID(TEXT(DEC2HEX(C16,4),"0"),LEN(TEXT(DEC2HEX(C16,4),"0"))-3,4),DEC2HEX(C16,4)),1,1),'двоичные коды'!A$1:B$16,2,0),1,1) -> 1 | H16: =MID(VLOOKUP(MID(IF(LEN(DEC2HEX(C16,4))>=4,MID(TEXT(DEC2HEX(C16,4),"0"),LEN(TEXT(DEC2HEX(C16,4),"0"))-3,4),DEC2HEX(C16,4)),1,1),'двоичные коды'!A$1:B$16,2,0),2,1) -> 0 | I16: =MID(VLOOKUP(MID(IF(LEN(DEC2HEX(C16,4))>=4,MID(TEXT(DEC2HEX(C16,4),"0"),LEN(TEXT(DEC2HEX(C16,4),"0"))-3,4),DEC2HEX(C16,4)),1,1),'двоичные коды'!A$1:B$16,2,0),3,1) -> 1 | J16: =MID(VLOOKUP(MID(IF(LEN(DEC2HEX(C16,4))>=4,MID(TEXT(DEC2HEX(C16,4),"0"),LEN(TEXT(DEC2HEX(C16,4),"0"))-3,4),DEC2HEX(C16,4)),1,1),'двоичные коды'!A$1:B$16,2,0),4,1) -> 0 | K16: . | L16: =MID(VLOOKUP(MID(IF(LEN(DEC2HEX(C16,4))>=4,MID(TEXT(DEC2HEX(C16,4),"0"),LEN(TEXT(DEC2HEX(C16,4),"0"))-3,4),DEC2HEX(C16,4)),2,1),'двоичные коды'!A$1:B$16,2,0),1,1) -> 1 | M16: =MID(VLOOKUP(MID(IF(LEN(DEC2HEX(C16,4))>=4,MID(TEXT(DEC2HEX(C16,4),"0"),LEN(TEXT(DEC2HEX(C16,4),"0"))-3,4),DEC2HEX(C16,4)),2,1),'двоичные коды'!A$1:B$16,2,0),2,1) -> 1 | N16: =MID(VLOOKUP(MID(IF(LEN(DEC2HEX(C16,4))>=4,MID(TEXT(DEC2HEX(C16,4),"0"),LEN(TEXT(DEC2HEX(C16,4),"0"))-3,4),DEC2HEX(C16,4)),2,1),'двоичные коды'!A$1:B$16,2,0),3,1) -> 0 | O16: =MID(VLOOKUP(MID(IF(LEN(DEC2HEX(C16,4))>=4,MID(TEXT(DEC2HEX(C16,4),"0"),LEN(TEXT(DEC2HEX(C16,4),"0"))-3,4),DEC2HEX(C16,4)),2,1),'двоичные коды'!A$1:B$16,2,0),4,1) -> 0 | P16: . | Q16: =MID(VLOOKUP(MID(IF(LEN(DEC2HEX(C16,4))>=4,MID(TEXT(DEC2HEX(C16,4),"0"),LEN(TEXT(DEC2HEX(C16,4),"0"))-3,4),DEC2HEX(C16,4)),3,1),'двоичные коды'!A$1:B$16,2,0),1,1) -> 1 | R16: =MID(VLOOKUP(MID(IF(LEN(DEC2HEX(C16,4))>=4,MID(TEXT(DEC2HEX(C16,4),"0"),LEN(TEXT(DEC2HEX(C16,4),"0"))-3,4),DEC2HEX(C16,4)),3,1),'двоичные коды'!A$1:B$16,2,0),2,1) -> 0 | S16: =MID(VLOOKUP(MID(IF(LEN(DEC2HEX(C16,4))>=4,MID(TEXT(DEC2HEX(C16,4),"0"),LEN(TEXT(DEC2HEX(C16,4),"0"))-3,4),DEC2HEX(C16,4)),3,1),'двоичные коды'!A$1:B$16,2,0),3,1) -> 1 | T16: =MID(VLOOKUP(MID(IF(LEN(DEC2HEX(C16,4))>=4,MID(TEXT(DEC2HEX(C16,4),"0"),LEN(TEXT(DEC2HEX(C16,4),"0"))-3,4),DEC2HEX(C16,4)),3,1),'двоичные коды'!A$1:B$16,2,0),4,1) -> 1 | U16: . | V16: =MID(VLOOKUP(MID(IF(LEN(DEC2HEX(C16,4))>=4,MID(TEXT(DEC2HEX(C16,4),"0"),LEN(TEXT(DEC2HEX(C16,4),"0"))-3,4),DEC2HEX(C16,4)),4,1),'двоичные коды'!A$1:B$16,2,0),1,1) -> 1 | W16: =MID(VLOOKUP(MID(IF(LEN(DEC2HEX(C16,4))>=4,MID(TEXT(DEC2HEX(C16,4),"0"),LEN(TEXT(DEC2HEX(C16,4),"0"))-3,4),DEC2HEX(C16,4)),4,1),'двоичные коды'!A$1:B$16,2,0),2,1) -> 1 | X16: =MID(VLOOKUP(MID(IF(LEN(DEC2HEX(C16,4))>=4,MID(TEXT(DEC2HEX(C16,4),"0"),LEN(TEXT(DEC2HEX(C16,4),"0"))-3,4),DEC2HEX(C16,4)),4,1),'двоичные коды'!A$1:B$16,2,0),3,1) -> 1 | Y16: =MID(VLOOKUP(MID(IF(LEN(DEC2HEX(C16,4))>=4,MID(TEXT(DEC2HEX(C16,4),"0"),LEN(TEXT(DEC2HEX(C16,4),"0"))-3,4),DEC2HEX(C16,4)),4,1),'двоичные коды'!A$1:B$16,2,0),4,1) -> 1
E19: B1(₂) | G19: =G5 -> 0 | H19: =H5 -> 0 | I19: =I5 -> 0 | J19: =J5 -> 0 | K19: =K5 -> . | L19: =L5 -> 1 | M19: =M5 -> 1 | N19: =N5 -> 0 | ... Y19: =Y5 -> 1 | AE19: X1(₁₀) | AG19: =C5 -> 3307 | AI19: =VLOOKUP(IF(AND(AG19>0,AG20>0),IF(AA22>0,1,2),IF(AND(AG19<0,AG20<0),IF(AA22<0,5,6),IF(AA22>0,4,3))),Комментарии!A1:B6,2,0) -> При сложении двух положительных слагаемых получено положительное число. Результат выполнения операции верный и корректный, совпадает с суммой десятичных эквивалентов.
D20: + | E20: B2(₂) | G20: =G6 -> 0 | H20: =H6 -> 1 | I20: =I6 -> 0 | J20: =J6 -> 0 | K20: =K6 -> . | L20: =L6 -> 1 | M20: =M6 -> 1 | N20: =N6 -> 1 | ... Y20: =Y6 -> 0 | AD20: + | AE20: X2(₁₀) | AG20: =C6 -> 20458
E21: ……… | F21: ……… | G21: … | H21: … | I21: … | J21: … | K21: … | L21: … | M21: … | N21: … | O21: … | P21: … | Q21: … | R21: … | S21: … | T21: … | U21: … | V21: … | W21: … | X21: … | Y21: … | AC21: = | AE21: …….. | AF21: …… | AG21: ……………..
G22: =MOD(G19+G20+H23,2) -> 0 | H22: =MOD(H19+H20+I23,2) -> 1 | I22: =MOD(I19+I20+J23,2) -> 0 | J22: =MOD(J19+J20+K23,2) -> 1 | K22: . | L22: =MOD(L19+L20+M23,2) -> 1 | M22: =MOD(M19+M20+N23,2) -> 1 | N22: =MOD(N19+N20+O23,2) -> 0 | O22: =MOD(O19+O20+P23,2) -> 0 | P22: . | Q22: =MOD(Q19+Q20+R23,2) -> 1 | R22: =MOD(R19+R20+S23,2) -> 1 | S22: =MOD(S19+S20+T23,2) -> 0 | T22: =MOD(T19+T20+U23,2) -> 1 | U22: . | V22: =MOD(V19+V20+W23,2) -> 0 | W22: =MOD(W19+W20+X23,2) -> 1 | X22: =MOD(X19+X20+Y23,2) -> 0 | Y22: =MOD(Y19+Y20+Z23,2) -> 1 | Z22: (₂)= | AA22: =IF(G22=1,-1*(32768-(H22*POWER(2,14)+I22*POWER(2,13)+J22*POWER(2,12)+L22*POWER(2,11)+M22*POWER(2,10)+N22*POWER(2,9)+O22*POWER(2,8)+Q22*POWER(2,7)+R22*POWER(2,6)+S22*POWER(2,5)+T22*POWER(2,4)+V22*POWER(2,3)+W22*POWER(2,2)+X22*POWER(2,1)+Y22*POWER(2,0))),H22*POWER(2,14)+I22*POWER(2,13)+J22*POWER(2,12)+L22*POWER(2,11)+M22*POWER(2,10)+N22*POWER(2,9)+O22*POWER(2,8)+Q22*POWER(2,7)+R22*POWER(2,6)+S22*POWER(2,5)+T22*POWER(2,4)+V22*POWER(2,3)+W22*POWER(2,2)+X22*POWER(2,1)+Y22*POWER(2,0)) -> 23765 | AB22: (₁₀) | AG22: =AG19+AG20 -> 23765 | AH22: (₁₀)
G23: =IF(G19+G20+H23<=1,0,1) -> 0 | H23: =IF(H19+H20+I23<=1,0,1) -> 0 | I23: =IF(I19+I20+J23<=1,0,1) -> 0 | J23: =IF(J19+J20+K23<=1,0,1) -> 0 | K23: =IF(L19+L20+M23<=1,0,1) -> 1 | L23: =IF(L19+L20+M23<=1,0,1) -> 1 | M23: =IF(M19+M20+N23<=1,0,1) -> 1 | N23: =IF(N19+N20+O23<=1,0,1) -> 1 | O23: =IF(O19+O20+P23<=1,0,1) -> 1 | P23: =IF(Q19+Q20+R23<=1,0,1) -> 1 | Q23: =IF(Q19+Q20+R23<=1,0,1) -> 1 | R23: =IF(R19+R20+S23<=1,0,1) -> 1 | S23: =IF(S19+S20+T23<=1,0,1) -> 1 | T23: =IF(T19+T20+U23<=1,0,1) -> 0 | U23: =IF(V19+V20+W23<=1,0,1) -> 1 | V23: =IF(V19+V20+W23<=1,0,1) -> 1 | W23: =IF(W19+W20+X23<=1,0,1) -> 0 | X23: =IF(X19+X20+Y23<=1,0,1) -> 1 | Y23: =IF(Y19+Y20+Z23<=1,0,1) -> 0 | Z23: 0
G25: CF = | J25: =G23 -> 0 | L25: PF= | O25: =IF(MOD(COUNTIF(Q22:Y22,1),2)=0,1,0) -> 0 | Q25: AF= | T25: =U23 -> 1 | V25: ZF= | Y25: =IF(COUNTIF(G22:Y22,1)=0,1,0) -> 0 | AA25: SF= | AB25: =G22 -> 0 | AC25: OF= | AD25: =IF(_xlfn.XOR(H23,G23),1,0) -> 0
E27: B2(₂) | G27: =G6 -> 0 | H27: =H6 -> 1 | I27: =I6 -> 0 | J27: =J6 -> 0 | K27: =K6 -> . | L27: =L6 -> 1 | M27: =M6 -> 1 | N27: =N6 -> 1 | ... Y27: =Y6 -> 0 | AE27: X2(₁₀) | AG27: =C6 -> 20458 | AI27: =VLOOKUP(IF(AND(AG27>0,AG28>0),IF(AA30>0,1,2),IF(AND(AG27<0,AG28<0),IF(AA30<0,5,6),IF(AA30>0,4,3))),Комментарии!A1:B6,2,0) -> При сложении двух положительных слагаемых получен отрицательный результат. ПЕРЕПОЛНЕНИЕ! Результат выполнения операции некорректный, не совпадает с суммой десятичных эквивалентов.
D28: + | E28: B3(₂) | G28: =G7 -> 0 | H28: =H7 -> 1 | I28: =I7 -> 0 | J28: =J7 -> 1 | K28: =K7 -> . | L28: =L7 -> 1 | M28: =M7 -> 1 | N28: =N7 -> 0 | ... Y28: =Y7 -> 1 | AD28: + | AE28: X3(₁₀) | AG28: =C7 -> 23765
E29: ……… | F29: ……… | G29: … | H29: … | I29: … | J29: … | K29: … | L29: … | M29: … | N29: … | O29: … | P29: … | Q29: … | R29: … | S29: … | T29: … | U29: … | V29: … | W29: … | X29: … | Y29: … | AC29: = | AE29: …….. | AF29: …… | AG29: ……………..
G30: =MOD(G27+G28+H31,2) -> 1 | H30: =MOD(H27+H28+I31,2) -> 0 | I30: =MOD(I27+I28+J31,2) -> 1 | J30: =MOD(J27+J28+K31,2) -> 0 | K30: . | L30: =MOD(L27+L28+M31,2) -> 1 | M30: =MOD(M27+M28+N31,2) -> 1 | N30: =MOD(N27+N28+O31,2) -> 0 | O30: =MOD(O27+O28+P31,2) -> 0 | P30: . | Q30: =MOD(Q27+Q28+R31,2) -> 1 | R30: =MOD(R27+R28+S31,2) -> 0 | S30: =MOD(S27+S28+T31,2) -> 1 | T30: =MOD(T27+T28+U31,2) -> 1 | U30: . | V30: =MOD(V27+V28+W31,2) -> 1 | W30: =MOD(W27+W28+X31,2) -> 1 | X30: =MOD(X27+X28+Y31,2) -> 1 | Y30: =MOD(Y27+Y28+Z31,2) -> 1 | Z30: (₂)= | AA30: =IF(G30=1,-1*(32768 - (H30*POWER(2,14)+I30*POWER(2,13)+J30*POWER(2,12)+L30*POWER(2,11)+M30*POWER(2,10)+N30*POWER(2,9)+O30*POWER(2,8)+Q30*POWER(2,7)+R30*POWER(2,6)+S30*POWER(2,5)+T30*POWER(2,4)+V30*POWER(2,3)+W30*POWER(2,2)+X30*POWER(2,1)+Y30*POWER(2,0))),H30*POWER(2,14)+I30*POWER(2,13)+J30*POWER(2,12)+L30*POWER(2,11)+M30*POWER(2,10)+N30*POWER(2,9)+O30*POWER(2,8)+Q30*POWER(2,7)+R30*POWER(2,6)+S30*POWER(2,5)+T30*POWER(2,4)+V30*POWER(2,3)+W30*POWER(2,2)+X30*POWER(2,1)+Y30*POWER(2,0)) -> -21313 | AB30: (₁₀) | AG30: =AG27+AG28 -> 44223 | AH30: (₁₀)
G31: =IF(G27+G28+H31<=1,0,1) -> 0 | H31: =IF(H27+H28+I31<=1,0,1) -> 1 | I31: =IF(I27+I28+J31<=1,0,1) -> 0 | J31: =IF(J27+J28+K31<=1,0,1) -> 1 | K31: =IF(L27+L28+M31<=1,0,1) -> 1 | L31: =IF(L27+L28+M31<=1,0,1) -> 1 | M31: =IF(M27+M28+N31<=1,0,1) -> 1 | N31: =IF(N27+N28+O31<=1,0,1) -> 1 | O31: =IF(O27+O28+P31<=1,0,1) -> 1 | P31: =IF(Q27+Q28+R31<=1,0,1) -> 1 | Q31: =IF(Q27+Q28+R31<=1,0,1) -> 1 | R31: =IF(R27+R28+S31<=1,0,1) -> 1 | S31: =IF(S27+S28+T31<=1,0,1) -> 0 | T31: =IF(T27+T28+U31<=1,0,1) -> 0 | U31: =IF(V27+V28+W31<=1,0,1) -> 0 | V31: =IF(V27+V28+W31<=1,0,1) -> 0 | W31: =IF(W27+W28+X31<=1,0,1) -> 0 | X31: =IF(X27+X28+Y31<=1,0,1) -> 0 | Y31: =IF(Y27+Y28+Z31<=1,0,1) -> 0 | Z31: 0
G33: CF = | J33: =G31 -> 0 | L33: PF= | O33: =IF(MOD(COUNTIF(Q30:Y30,1),2)=0,1,0) -> 0 | Q33: AF= | T33: =U31 -> 0 | V33: ZF= | Y33: =IF(COUNTIF(G30:Y30,1)=0,1,0) -> 0 | AA33: SF= | AB33: =G30 -> 1 | AC33: OF= | AD33: =IF(_xlfn.XOR(H31,G31),1,0) -> 1
E35: B2(₂) | G35: =G6 -> 0 | H35: =H6 -> 1 | I35: =I6 -> 0 | J35: =J6 -> 0 | K35: =K6 -> . | L35: =L6 -> 1 | M35: =M6 -> 1 | N35: =N6 -> 1 | ... Y35: =Y6 -> 0 | AE35: X2(₁₀) | AG35: =C6 -> 20458 | AI35: =VLOOKUP(IF(AND(AG35>0,AG36>0),IF(AA38>0,1,2),IF(AND(AG35<0,AG36<0),IF(AA38<0,5,6),IF(AA38>0,4,3))),Комментарии!A1:B6,2,0) -> При сложении положительного и отрицательного слагаемых получено положительное число. Перенос из старшего разряда не учитывается. Результат выполнения операции верный и корректный, совпадает с суммой десятичных эквивалентов.
D36: + | E36: B7(₂) | G36: =G11 -> 1 | H36: =H11 -> 1 | I36: =I11 -> 1 | J36: =J11 -> 1 | K36: =K11 -> . | L36: =L11 -> 0 | M36: =M11 -> 0 | N36: =N11 -> 1 | ... Y36: =Y11 -> 1 | AD36: + | AE36: X7(₁₀) | AG36: =C11 -> -3307
E37: ……… | F37: ……… | G37: … | H37: … | I37: … | J37: … | K37: … | L37: … | M37: … | N37: … | O37: … | P37: … | Q37: … | R37: … | S37: … | T37: … | U37: … | V37: … | W37: … | X37: … | Y37: … | AC37: = | AE37: …….. | AF37: …… | AG37: ……………..
G38: =MOD(G35+G36+H39,2) -> 0 | H38: =MOD(H35+H36+I39,2) -> 1 | I38: =MOD(I35+I36+J39,2) -> 0 | J38: =MOD(J35+J36+K39,2) -> 0 | K38: . | L38: =MOD(L35+L36+M39,2) -> 0 | M38: =MOD(M35+M36+N39,2) -> 0 | N38: =MOD(N35+N36+O39,2) -> 1 | O38: =MOD(O35+O36+P39,2) -> 0 | P38: . | Q38: =MOD(Q35+Q36+R39,2) -> 1 | R38: =MOD(R35+R36+S39,2) -> 1 | S38: =MOD(S35+S36+T39,2) -> 1 | T38: =MOD(T35+T36+U39,2) -> 1 | U38: . | V38: =MOD(V35+V36+W39,2) -> 1 | W38: =MOD(W35+W36+X39,2) -> 1 | X38: =MOD(X35+X36+Y39,2) -> 1 | Y38: =MOD(Y35+Y36+Z39,2) -> 1 | Z38: (₂)= | AA38: =IF(G38=1,-1*(32768 - (H38*POWER(2,14)+I38*POWER(2,13)+J38*POWER(2,12)+L38*POWER(2,11)+M38*POWER(2,10)+N38*POWER(2,9)+O38*POWER(2,8)+Q38*POWER(2,7)+R38*POWER(2,6)+S38*POWER(2,5)+T38*POWER(2,4)+V38*POWER(2,3)+W38*POWER(2,2)+X38*POWER(2,1)+Y38*POWER(2,0))),H38*POWER(2,14)+I38*POWER(2,13)+J38*POWER(2,12)+L38*POWER(2,11)+M38*POWER(2,10)+N38*POWER(2,9)+O38*POWER(2,8)+Q38*POWER(2,7)+R38*POWER(2,6)+S38*POWER(2,5)+T38*POWER(2,4)+V38*POWER(2,3)+W38*POWER(2,2)+X38*POWER(2,1)+Y38*POWER(2,0)) -> 17151 | AB38: (₁₀) | AG38: =AG35+AG36 -> 17151 | AH38: (₁₀)
G39: =IF(G35+G36+H39<=1,0,1) -> 1 | H39: =IF(H35+H36+I39<=1,0,1) -> 1 | I39: =IF(I35+I36+J39<=1,0,1) -> 1 | J39: =IF(J35+J36+K39<=1,0,1) -> 1 | K39: =IF(L35+L36+M39<=1,0,1) -> 1 | L39: =IF(L35+L36+M39<=1,0,1) -> 1 | M39: =IF(M35+M36+N39<=1,0,1) -> 1 | N39: =IF(N35+N36+O39<=1,0,1) -> 1 | O39: =IF(O35+O36+P39<=1,0,1) -> 1 | P39: =IF(Q35+Q36+R39<=1,0,1) -> 0 | Q39: =IF(Q35+Q36+R39<=1,0,1) -> 0 | R39: =IF(R35+R36+S39<=1,0,1) -> 0 | S39: =IF(S35+S36+T39<=1,0,1) -> 0 | T39: =IF(T35+T36+U39<=1,0,1) -> 0 | U39: =IF(V35+V36+W39<=1,0,1) -> 0 | V39: =IF(V35+V36+W39<=1,0,1) -> 0 | W39: =IF(W35+W36+X39<=1,0,1) -> 0 | X39: =IF(X35+X36+Y39<=1,0,1) -> 0 | Y39: =IF(Y35+Y36+Z39<=1,0,1) -> 0 | Z39: 0
G41: CF = | J41: =G39 -> 1 | L41: PF= | O41: =IF(MOD(COUNTIF(Q38:Y38,1),2)=0,1,0) -> 1 | Q41: AF= | T41: =U39 -> 0 | V41: ZF= | Y41: =IF(COUNTIF(G38:Y38,1)=0,1,0) -> 0 | AA41: SF= | AB41: =G38 -> 0 | AC41: OF= | AD41: =IF(_xlfn.XOR(H39,G39),1,0) -> 0
E43: B7(₂) | G43: =G11 -> 1 | H43: =H11 -> 1 | I43: =I11 -> 1 | J43: =J11 -> 1 | K43: =K11 -> . | L43: =L11 -> 0 | M43: =M11 -> 0 | N43: =N11 -> 1 | ... Y43: =Y11 -> 1 | AE43: X7(₁₀) | AG43: =C11 -> -3307 | AI43: =VLOOKUP(IF(AND(AG43>0,AG44>0),IF(AA46>0,1,2),IF(AND(AG43<0,AG44<0),IF(AA46<0,5,6),IF(AA46>0,4,3))),Комментарии!A1:B6,2,0) -> При сложении двух отрицательных слагаемых получено отрицательное число. Перенос из старшего разряда не учитывается. Результат выполнения операции верный и корректный, совпадает с суммой десятичных эквивалентов.
D44: + | E44: B8(₂) | G44: =G12 -> 1 | H44: =H12 -> 0 | I44: =I12 -> 1 | J44: =J12 -> 1 | K44: =K12 -> . | L44: =L12 -> 0 | M44: =M12 -> 0 | N44: =N12 -> 0 | ... Y44: =Y12 -> 0 | AD44: + | AE44: X8(₁₀) | AG44: =C12 -> -20458
E45: ……… | F45: ……… | G45: … | H45: … | I45: … | J45: … | K45: … | L45: … | M45: … | N45: … | O45: … | P45: … | Q45: … | R45: … | S45: … | T45: … | U45: … | V45: … | W45: … | X45: … | Y45: … | AC45: = | AE45: …….. | AF45: …… | AG45: ……………..
G46: =MOD(G43+G44+H47,2) -> 1 | H46: =MOD(H43+H44+I47,2) -> 0 | I46: =MOD(I43+I44+J47,2) -> 1 | J46: =MOD(J43+J44+K47,2) -> 0 | K46: . | L46: =MOD(L43+L44+M47,2) -> 0 | M46: =MOD(M43+M44+N47,2) -> 0 | N46: =MOD(N43+N44+O47,2) -> 1 | O46: =MOD(O43+O44+P47,2) -> 1 | P46: . | Q46: =MOD(Q43+Q44+R47,2) -> 0 | R46: =MOD(R43+R44+S47,2) -> 0 | S46: =MOD(S43+S44+T47,2) -> 1 | T46: =MOD(T43+T44+U47,2) -> 0 | U46: . | V46: =MOD(V43+V44+W47,2) -> 1 | W46: =MOD(W43+W44+X47,2) -> 0 | X46: =MOD(X43+X44+Y47,2) -> 1 | Y46: =MOD(Y43+Y44+Z47,2) -> 1 | Z46: (₂)= | AA46: =IF(G46=1,-1*(32768 - (H46*POWER(2,14)+I46*POWER(2,13)+J46*POWER(2,12)+L46*POWER(2,11)+M46*POWER(2,10)+N46*POWER(2,9)+O46*POWER(2,8)+Q46*POWER(2,7)+R46*POWER(2,6)+S46*POWER(2,5)+T46*POWER(2,4)+V46*POWER(2,3)+W46*POWER(2,2)+X46*POWER(2,1)+Y46*POWER(2,0))),H46*POWER(2,14)+I46*POWER(2,13)+J46*POWER(2,12)+L46*POWER(2,11)+M46*POWER(2,10)+N46*POWER(2,9)+O46*POWER(2,8)+Q46*POWER(2,7)+R46*POWER(2,6)+S46*POWER(2,5)+T46*POWER(2,4)+V46*POWER(2,3)+W46*POWER(2,2)+X46*POWER(2,1)+Y46*POWER(2,0)) -> -23765 | AB46: (₁₀) | AG46: =AG43+AG44 -> -23765 | AH46: (₁₀)
G47: =IF(G43+G44+H47<=1,0,1) -> 1 | H47: =IF(H43+H44+I47<=1,0,1) -> 1 | I47: =IF(I43+I44+J47<=1,0,1) -> 1 | J47: =IF(J43+J44+K47<=1,0,1) -> 1 | K47: =IF(L43+L44+M47<=1,0,1) -> 0 | L47: =IF(L43+L44+M47<=1,0,1) -> 0 | M47: =IF(M43+M44+N47<=1,0,1) -> 0 | N47: =IF(N43+N44+O47<=1,0,1) -> 0 | O47: =IF(O43+O44+P47<=1,0,1) -> 0 | P47: =IF(Q43+Q44+R47<=1,0,1) -> 0 | Q47: =IF(Q43+Q44+R47<=1,0,1) -> 0 | R47: =IF(R43+R44+S47<=1,0,1) -> 0 | S47: =IF(S43+S44+T47<=1,0,1) -> 0 | T47: =IF(T43+T44+U47<=1,0,1) -> 1 | U47: =IF(V43+V44+W47<=1,0,1) -> 0 | V47: =IF(V43+V44+W47<=1,0,1) -> 0 | W47: =IF(W43+W44+X47<=1,0,1) -> 1 | X47: =IF(X43+X44+Y47<=1,0,1) -> 0 | Y47: =IF(Y43+Y44+Z47<=1,0,1) -> 0 | Z47: 0
G49: CF = | J49: =G47 -> 1 | L49: PF= | O49: =IF(MOD(COUNTIF(Q46:Y46,1),2)=0,1,0) -> 1 | Q49: AF= | T49: =U47 -> 0 | V49: ZF= | Y49: =IF(COUNTIF(G46:Y46,1)=0,1,0) -> 0 | AA49: SF= | AB49: =G46 -> 1 | AC49: OF= | AD49: =IF(_xlfn.XOR(H47,G47),1,0) -> 0
E51: B8(₂) | G51: =G12 -> 1 | H51: =H12 -> 0 | I51: =I12 -> 1 | J51: =J12 -> 1 | K51: =K12 -> . | L51: =L12 -> 0 | M51: =M12 -> 0 | N51: =N12 -> 0 | ... Y51: =Y12 -> 0 | AE51: X8(₁₀) | AG51: =C12 -> -20458 | AI51: =VLOOKUP(IF(AND(AG51>0,AG52>0),IF(AA54>0,1,2),IF(AND(AG51<0,AG52<0),IF(AA54<0,5,6),IF(AA54>0,4,3))),Комментарии!A1:B6,2,0) -> При сложении двух отрицательных слагаемых получено положительное число. ПЕРЕПОЛНЕНИЕ! Результат выполнения операции некорректный, не совпадает с суммой десятичных эквивалентов.
D52: + | E52: B9(₂) | G52: =G13 -> 1 | H52: =H13 -> 0 | I52: =I13 -> 1 | J52: =J13 -> 0 | K52: =K13 -> . | L52: =L13 -> 0 | M52: =M13 -> 0 | N52: =N13 -> 1 | ... Y52: =Y13 -> 1 | AD52: + | AE52: X9(₁₀) | AG52: =C13 -> -23765
...

Sheet двоичные коды
A1: ="0" -> 0 | B1: ="0000" -> 0000
A2: ="1" -> 1 | B2: ="0001" -> 0001
A3: ="2" -> 2 | B3: ="0010" -> 0010
A4: ="3" -> 3 | B4: ="0011" -> 0011
A5: ="4" -> 4 | B5: ="0100" -> 0100
A6: ="5" -> 5 | B6: ="0101" -> 0101
A7: ="6" -> 6 | B7: ="0110" -> 0110
A8: ="7" -> 7 | B8: ="0111" -> 0111
A9: ="8" -> 8 | B9: ="1000" -> 1000
A10: ="9" -> 9 | B10: ="1001" -> 1001
A11: ="A" -> A | B11: ="1010" -> 1010
A12: ="B" -> B | B12: ="1011" -> 1011
A13: ="C" -> C | B13: ="1100" -> 1100
A14: ="D" -> D | B14: ="1101" -> 1101
A15: ="E" -> E | B15: ="1110" -> 1110
A16: ="F" -> F | B16: ="1111" -> 1111
